Workbook

Sheet Leia-me
A1: Relatório de SKUs – nova codificação de produtos
A2: Para revisão da área técnica · base: cadastro do sistema em 14/10/2026 · nenhuma alteração foi feita no sistema
A4: Resumo por família e status
A5: Família | B5: Total | C5: Conforme | D5: Proposto | E5: Pendente
A6: PF – Produto final (gelato/picolé) | B6: =COUNTIF(SKUs!$A$5:$A$327,"PF") -> 74 | C6: =COUNTIFS(SKUs!$A$5:$A$327,"PF",SKUs!$N$5:$N$327,"Conforme") -> 1 | D6: =COUNTIFS(SKUs!$A$5:$A$327,"PF",SKUs!$N$5:$N$327,"Proposto") -> 47 | E6: =COUNTIFS(SKUs!$A$5:$A$327,"PF",SKUs!$N$5:$N$327,"Pendente") -> 26
A7: MP – Matéria-prima | B7: =COUNTIF(SKUs!$A$5:$A$327,"MP") -> 174 | C7: =COUNTIFS(SKUs!$A$5:$A$327,"MP",SKUs!$N$5:$N$327,"Conforme") -> 26 | D7: =COUNTIFS(SKUs!$A$5:$A$327,"MP",SKUs!$N$5:$N$327,"Proposto") -> 147 | E7: =COUNTIFS(SKUs!$A$5:$A$327,"MP",SKUs!$N$5:$N$327,"Pendente") -> 1
A8: EM – Embalagem | B8: =COUNTIF(SKUs!$A$5:$A$327,"EM") -> 43 | C8: =COUNTIFS(SKUs!$A$5:$A$327,"EM",SKUs!$N$5:$N$327,"Conforme") -> 0 | D8: =COUNTIFS(SKUs!$A$5:$A$327,"EM",SKUs!$N$5:$N$327,"Proposto") -> 43 | E8: =COUNTIFS(SKUs!$A$5:$A$327,"EM",SKUs!$N$5:$N$327,"Pendente") -> 0
A9: Sem família no modelo | B9: =COUNTIF(SKUs!$A$5:$A$327,"—") -> 32 | C9: =COUNTIFS(SKUs!$A$5:$A$327,"—",SKUs!$N$5:$N$327,"Conforme") -> 0 | D9: =COUNTIFS(SKUs!$A$5:$A$327,"—",SKUs!$N$5:$N$327,"Proposto") -> 0 | E9: =COUNTIFS(SKUs!$A$5:$A$327,"—",SKUs!$N$5:$N$327,"Pendente") -> 32
A10: Total | B10: =SUM(B6:B9) -> 323 | C10: =SUM(C6:C9) -> 27 | D10: =SUM(D6:D9) -> 237 | E10: =SUM(E6:E9) -> 59
A11: SKUs duplicados (devem ser resolvidos) | B11: =COUNTIF(SKUs!$O$5:$O$327,"DUPLICADO") -> 4
A13: Formato do SKU
A14: PF (gelato/picolé): Tipo(2) + Sabor(3) + Tamanho(2) + Linha(2) ex.: GL10136TR = Gelato · 101 Chocolate Belga · Pote 360 g · Tradicional
A15: MP (matéria-prima): Tipo(2) + Categoria(2) + Descrição(3) + Armazenamento(2) ex.: MPLT100RF = Leite integral refrigerado
A16: EM (embalagem): Tipo(2) + Categoria(2) + Descrição(3) + Complemento(2, opcional) ex.: EMPR400 = Palito
A18: Como ler o Status
A19: Conforme: todos os blocos vêm das tabelas do modelo, da lista de frutas ou de exemplo explícito do modelo.
A20: Proposto: algum código foi criado ou assumido nesta análise (sabor novo, categoria nova, tamanho novo, embalagem assumida). Ver coluna "Blocos propostos / assumidos".
A21: Pendente: faltam informações para definir o SKU (ex.: gramatura do picolé) ou não há regra no modelo (ex.: itens de limpeza e escritório).
A23: Premissas gerais
A24: 1. O armazenamento (SC/RF/CG/AC) de todas as matérias-primas foi inferido pelo tipo de produto, porque o sistema não registra essa informação; mesmo os MPs "Conforme" precisam dessa validação.
A25: 2. Códigos novos seguem a sequência da faixa de cada categoria/classe, em ordem alfabética (ou na ordem do cadastro atual para MP), preservando os exemplos fixados pelos modelos.
A26: 3. Gelatos cadastrados a granel foram assumidos como caixa de 6 kg (C1).
... A34: Alertas de cadastro – duplicidades e problemas no cadastro atual.

Sheet SKUs
A1: SKUs propostos para todos os produtos cadastrados no sistema
A2: Posição do cadastro em 14/10/2026 (somente leitura; nenhuma alteração feita no sistema). SKU = Bloco 1 & Bloco 2 & Bloco 3 & Bloco 4, conforme modelos de 23/09/2026. Status: Conforme = só códigos do modelo/lista de frutas · Proposto = ao menos um código criado/assumido nesta análise · Pendente = sem SKU definitivo.
A4: Família | B4: Cadastro de origem | C4: Código atual | D4: Produto atual | E4: Un. atual | F4: Estoque atual | G4: Bloco 1 (Tipo) | H4: Bloco 2 (PF: Sabor · MP/EM: Categoria) | I4: Bloco 3 (PF: Tamanho · MP/EM: Descrição) | J4: Bloco 4 (PF: Linha · MP: Armazen. · EM: Compl.) | K4: SKU NOVO | L4: Nome padronizado | M4: Leitura dos blocos | N4: Status | O4: Unicidade | P4: Blocos propostos / assumidos | Q4: Observações para revisão | R4: Decisão da área técnica
A5: PF | B5: Produto Acabado | C5: PF-00010 | D5: Banoffee | F5: 0 | G5: GL | H5: 102 | I5: C1 | J5: TR | K5: =IF(OR(G5="",H5="",I5=""),"",G5&H5&I5&J5) -> GL102C1TR | L5: Gelato Banoffee - Caixa 6 kg - Tradicional | M5: GL = Gelato | 102 = Ao Leite – Banoffee | C1 = Caixa 6 kg | TR = Tradicional | N5: Proposto | O5: =IF(K5="","",IF(COUNTIF($K$5:$K$327,K5)>1,"DUPLICADO","Único")) -> Único | P5: B2 (código de sabor novo); B3 (embalagem C1 assumida – item cadastrado a granel) | Q5: Unidade cadastrada "vazia" diverge do padrão Kg dos demais gelatos.
A6: PF | B6: Produto Acabado | C6: PF-00011 | D6: Chocolate Intenso | E6: Kg | F6: 233 | G6: GL | H6: 106 | I6: C1 | J6: TR | K6: =IF(OR(G6="",H6="",I6=""),"",G6&H6&I6&J6) -> GL106C1TR | L6: Gelato Chocolate Intenso - Caixa 6 kg - Tradicional | M6: GL = Gelato | 106 = Ao Leite – Chocolate Intenso | C1 = Caixa 6 kg | TR = Tradicional | N6: Proposto | O6: =IF(K6="","",IF(COUNTIF($K$5:$K$327,K6)>1,"DUPLICADO","Único")) -> Único | P6: B2 (código de sabor novo); B3 (embalagem C1 assumida – item cadastrado a granel)
A7: PF | B7: Produto Acabado | C7: PF-00012 | D7: Chocolate Branco | E7: Kg | F7: 0 | G7: GL | H7: 103 | I7: C1 | J7: TR | K7: =IF(OR(G7="",H7="",I7=""),"",G7&H7&I7&J7) -> GL103C1TR | L7: Gelato Chocolate Branco - Caixa 6 kg - Tradicional | M7: GL = Gelato | 103 = Ao Leite – Chocolate Branco | C1 = Caixa 6 kg | TR = Tradicional | N7: Proposto | O7: =IF(K7="","",IF(COUNTIF($K$5:$K$327,K7)>1,"DUPLICADO","Único")) -> Único | P7: B2 (código de sabor novo); B3 (embalagem C1 assumida – item cadastrado a granel)
A8: PF | B8: Produto Acabado | C8: PF-00013 | D8: Chocolate Dubai | E8: Kg | F8: 125 | G8: GL | H8: 105 | I8: C1 | J8: TR | K8: =IF(OR(G8="",H8="",I8=""),"",G8&H8&I8&J8) -> GL105C1TR | L8: Gelato Chocolate Dubai - Caixa 6 kg - Tradicional | M8: GL = Gelato | 105 = Ao Leite – Chocolate Dubai | C1 = Caixa 6 kg | TR = Tradicional | N8: Proposto | O8: =IF(K8="","",IF(COUNTIF($K$5:$K$327,K8)>1,"DUPLICADO","Único")) -> Único | P8: B2 (código de sabor novo); B3 (embalagem C1 assumida – item cadastrado a granel)
A9: PF | B9: Produto Acabado | C9: PF-00014 | D9: Coco Branco | E9: Kg | F9: 51 | G9: GL | H9: 107 | I9: C1 | J9: TR | K9: =IF(OR(G9="",H9="",I9=""),"",G9&H9&I9&J9) -> GL107C1TR | L9: Gelato Coco Branco - Caixa 6 kg - Tradicional | M9: GL = Gelato | 107 = Ao Leite – Coco Branco | C1 = Caixa 6 kg | TR = Tradicional | N9: Proposto | O9: =IF(K9="","",IF(COUNTIF($K$5:$K$327,K9)>1,"DUPLICADO","Único")) -> Único | P9: B2 (código de sabor novo); B3 (embalagem C1 assumida – item cadastrado a granel)
A10: PF | B10: Produto Acabado | C10: PF-00015 | D10: Doce de leite | E10: Kg | F10: 185 | G10: GL | H10: 110 | I10: C1 | J10: TR | K10: =IF(OR(G10="",H10="",I10=""),"",G10&H10&I10&J10) -> GL110C1TR | L10: Gelato Doce de Leite - Caixa 6 kg - Tradicional | M10: GL = Gelato | 110 = Ao Leite – Doce de Leite | C1 = Caixa 6 kg | TR = Tradicional | N10: Proposto | O10: =IF(K10="","",IF(COUNTIF($K$5:$K$327,K10)>1,"DUPLICADO","Único")) -> Único | P10: B2 (código de sabor novo); B3 (embalagem C1 assumida – item cadastrado a granel)
A11: PF | B11: Produto Acabado | C11: PF-00016 | D11: Floresta Negra | E11: Kg | F11: 0 | G11: GL | H11: 111 | I11: C1 | J11: TR | K11: =IF(OR(G11="",H11="",I11=""),"",G11&H11&I11&J11) -> GL111C1TR | L11: Gelato Floresta Negra - Caixa 6 kg - Tradicional | M11: GL = Gelato | 111 = Ao Leite – Floresta Negra | C1 = Caixa 6 kg | TR = Tradicional | N11: Proposto | O11: =IF(K11="","",IF(COUNTIF($K$5:$K$327,K11)>1,"DUPLICADO","Único")) -> Único | P11: B2 (código de sabor novo); B3 (embalagem C1 assumida – item cadastrado a granel)
A12: PF | B12: Produto Acabado | C12: PF-00017 | D12: Sorbet Frutas Vermelhas | E12: Kg | F12: 71 | G12: GL | H12: 201 | I12: C1 | J12: TR | K12: =IF(OR(G12="",H12="",I12=""),"",G12&H12&I12&J12) -> GL201C1TR | L12: Gelato Sorbet Frutas Vermelhas - Caixa 6 kg - Tradicional | M12: GL = Gelato | 201 = Sorbet – Frutas Vermelhas | C1 = Caixa 6 kg | TR = Tradicional | N12: Proposto | O12: =IF(K12="","",IF(COUNTIF($K$5:$K$327,K12)>1,"DUPLICADO","Único")) -> DUPLICADO | P12: B2 (código de sabor novo); B3 (embalagem C1 assumida – item cadastrado a granel) | Q12: Possível duplicidade com PF-00082 (mesmo sabor/embalagem → mesmo SKU).
A13: PF | B13: Produto Acabado | C13: PF-00018 | D13: Limão | F13: 0 | G13: GL | H13: 203 | I13: C1 | J13: TR | K13: =IF(OR(G13="",H13="",I13=""),"",G13&H13&I13&J13) -> GL203C1TR | L13: Gelato Sorbet Limão - Caixa 6 kg - Tradicional | M13: GL = Gelato | 203 = Sorbet – Limão | C1 = Caixa 6 kg | TR = Tradicional | N13: Proposto | O13: =IF(K13="","",IF(COUNTIF($K$5:$K$327,K13)>1,"DUPLICADO","Único")) -> Único | P13: B2 (código de sabor novo); B3 (embalagem C1 assumida – item cadastrado a granel) | Q13: Unidade cadastrada "vazia" diverge do padrão Kg dos demais gelatos. Classificado como sorbet pela OP "Sorbet Limão".
A14: PF | B14: Produto Acabado | C14: PF-00019 | D14: Sorbet Manga | E14: Kg | F14: 0 | G14: GL | H14: 200 | I14: C1 | J14: TR | K14: =IF(OR(G14="",H14="",I14=""),"",G14&H14&I14&J14) -> GL200C1TR | L14: Gelato Sorbet Manga - Caixa 6 kg - Tradicional | M14: GL = Gelato | 200 = Sorbet – Manga | C1 = Caixa 6 kg | TR = Tradicional | N14: Proposto | O14: =IF(K14="","",IF(COUNTIF($K$5:$K$327,K14)>1,"DUPLICADO","Único")) -> DUPLICADO | P14: B3 (embalagem C1 assumida – item cadastrado a granel) | Q14: Possível duplicidade com PF-00081 (mesmo sabor/embalagem → mesmo SKU). Sabor 200 é exemplo "a confirmar" no modelo.
A15: PF | B15: Produto Acabado | C15: PF-00020 | D15: Sorbet Morango | E15: Kg | F15: 38 | G15: GL | H15: 206 | I15: C1 | J15: TR | K15: =IF(OR(G15="",H15="",I15=""),"",G15&H15&I15&J15) -> GL206C1TR | L15: Gelato Sorbet Morango - Caixa 6 kg - Tradicional | M15: GL = Gelato | 206 = Sorbet – Morango | C1 = Caixa 6 kg | TR = Tradicional | N15: Proposto | O15: =IF(K15="","",IF(COUNTIF($K$5:$K$327,K15)>1,"DUPLICADO","Único")) -> Único | P15: B2 (código de sabor novo); B3 (embalagem C1 assumida – item cadastrado a granel)
A16: PF | B16: Produto Acabado | C16: PF-00021 | D16: Nocciola Crocante | E16: Kg | F16: 0 | G16: GL | H16: 118 | I16: C1 | J16: TR | K16: =IF(OR(G16="",H16="",I16=""),"",G16&H16&I16&J16) -> GL118C1TR | L16: Gelato Nocciola Crocante - Caixa 6 kg - Tradicional | M16: GL = Gelato | 118 = Ao Leite – Nocciola Crocante | C1 = Caixa 6 kg | TR = Tradicional | N16: Proposto | O16: =IF(K16="","",IF(COUNTIF($K$5:$K$327,K16)>1,"DUPLICADO","Único")) -> Único | P16: B2 (código de sabor novo); B3 (embalagem C1 assumida – item cadastrado a granel)
A17: PF | B17: Produto Acabado | C17: PF-00022 | D17: Pavlova | E17: Kg | F17: 114 | G17: GL | H17: 120 | I17: C1 | J17: TR | K17: =IF(OR(G17="",H17="",I17=""),"",G17&H17&I17&J17) -> GL120C1TR | L17: Gelato Pavlova - Caixa 6 kg - Tradicional | M17: GL = Gelato | 120 = Ao Leite – Pavlova | C1 = Caixa 6 kg | TR = Tradicional | N17: Proposto | O17: =IF(K17="","",IF(COUNTIF($K$5:$K$327,K17)>1,"DUPLICADO","Único")) -> Único | P17: B2 (código de sabor novo); B3 (embalagem C1 assumida – item cadastrado a granel)
A18: PF | B18: Produto Acabado | C18: PF-00023 | D18: Pistache | E18: Kg | F18: 251 | G18: GL | H18: 121 | I18: C1 | J18: TR | K18: =IF(OR(G18="",H18="",I18=""),"",G18&H18&I18&J18) -> GL121C1TR | L18: Gelato Pistache - Caixa 6 kg - Tradicional | M18: GL = Gelato | 121 = Ao Leite – Pistache | C1 = Caixa 6 kg | TR = Tradicional | N18: Proposto | O18: =IF(K18="","",IF(COUNTIF($K$5:$K$327,K18)>1,"DUPLICADO","Único")) -> Único | P18: B2 (código de sabor novo); B3 (embalagem C1 assumida – item cadastrado a granel)
A19: PF | B19: Produto Acabado | C19: PF-00024 | D19: Rosso Nero | E19: Kg | F19: 38 | G19: GL | H19: 122 | I19: C1 | J19: TR | K19: =IF(OR(G19="",H19="",I19=""),"",G19&H19&I19&J19) -> GL122C1TR | L19: Gelato Rosso Nero - Caixa 6 kg - Tradicional | M19: GL = Gelato | 122 = Ao Leite – Rosso Nero | C1 = Caixa 6 kg | TR = Tradicional | N19: Proposto | O19: =IF(K19="","",IF(COUNTIF($K$5:$K$327,K19)>1,"DUPLICADO","Único")) -> Único | P19: B2 (código de sabor novo); B3 (embalagem C1 assumida – item cadastrado a granel)
A20: PF | B20: Produto Acabado | C20: PF-00025 | D20: Snichelato | E20: Kg | F20: 0 | G20: GL | H20: 123 | I20: C1 | J20: TR | K20: =IF(OR(G20="",H20="",I20=""),"",G20&H20&I20&J20) -> GL123C1TR | L20: Gelato Snichelato - Caixa 6 kg - Tradicional | M20: GL = Gelato | 123 = Ao Leite – Snichelato | C1 = Caixa 6 kg | TR = Tradicional | N20: Proposto | O20: =IF(K20="","",IF(COUNTIF($K$5:$K$327,K20)>1,"DUPLICADO","Único")) -> Único | P20: B2 (código de sabor novo); B3 (embalagem C1 assumida – item cadastrado a granel)
A21: PF | B21: Produto Acabado | C21: PF-00026 | D21: Speculoos | E21: Kg | F21: 83 | G21: GL | H21: 124 | I21: C1 | J21: TR | K21: =IF(OR(G21="",H21="",I21=""),"",G21&H21&I21&J21) -> GL124C1TR | L21: Gelato Speculoos - Caixa 6 kg - Tradicional | M21: GL = Gelato | 124 = Ao Leite – Speculoos | C1 = Caixa 6 kg | TR = Tradicional | N21: Proposto | O21: =IF(K21="","",IF(COUNTIF($K$5:$K$327,K21)>1,"DUPLICADO","Único")) -> Único | P21: B2 (código de sabor novo); B3 (embalagem C1 assumida – item cadastrado a granel)
A22: PF | B22: Produto Acabado | C22: PF-00027 | D22: Tiramisù | E22: Kg | F22: 26 | G22: GL | H22: 126 | I22: C1 | J22: TR | K22: =IF(OR(G22="",H22="",I22=""),"",G22&H22&I22&J22) -> GL126C1TR | L22: Gelato Tiramisù - Caixa 6 kg - Tradicional | M22: GL = Gelato | 126 = Ao Leite – Tiramisù | C1 = Caixa 6 kg | TR = Tradicional | N22: Proposto | O22: =IF(K22="","",IF(COUNTIF($K$5:$K$327,K22)>1,"DUPLICADO","Único")) -> Único | P22: B2 (código de sabor novo); B3 (embalagem C1 assumida – item cadastrado a granel)
A23: PF | B23: Produto Acabado | C23: PF-00028 | D23: Torta de Limão | E23: Cx | F23: 0 | G23: GL | H23: 127 | I23: C1 | J23: TR | K23: =IF(OR(G23="",H23="",I23=""),"",G23&H23&I23&J23) -> GL127C1TR | L23: Gelato Torta de Limão - Caixa 6 kg - Tradicional | M23: GL = Gelato | 127 = Ao Leite – Torta de Limão | C1 = Caixa 6 kg | TR = Tradicional | N23: Proposto | O23: =IF(K23="","",IF(COUNTIF($K$5:$K$327,K23)>1,"DUPLICADO","Único")) -> Único | P23: B2 (código de sabor novo); B3 (embalagem C1 assumida – item cadastrado a granel) | Q23: Unidade cadastrada "Cx" diverge do padrão Kg dos demais gelatos.
A24: PF | B24: Produto Acabado | C24: PF-00029 | D24: Yogurt com Amarena | E24: Kg | F24: 65 | G24: GL | H24: 128 | I24: C1 | J24: TR | K24: =IF(OR(G24="",H24="",I24=""),"",G24&H24&I24&J24) -> GL128C1TR | L24: Gelato Yogurt com Amarena - Caixa 6 kg - Tradicional | M24: GL = Gelato | 128 = Ao Leite – Yogurt com Amarena | C1 = Caixa 6 kg | TR = Tradicional | N24: Proposto | O24: =IF(K24="","",IF(COUNTIF($K$5:$K$327,K24)>1,"DUPLICADO","Único")) -> Único | P24: B2 (código de sabor novo); B3 (embalagem C1 assumida – item cadastrado a granel)
A25: PF | B25: Produto Acabado | C25: PF-00030 | D25: Gianduia | E25: Cx | F25: 100 | G25: GL | H25: 113 | I25: C1 | J25: TR | K25: =IF(OR(G25="",H25="",I25=""),"",G25&H25&I25&J25) -> GL113C1TR | L25: Gelato Gianduia - Caixa 6 kg - Tradicional | M25: GL = Gelato | 113 = Ao Leite – Gianduia | C1 = Caixa 6 kg | TR = Tradicional | N25: Proposto | O25: =IF(K25="","",IF(COUNTIF($K$5:$K$327,K25)>1,"DUPLICADO","Único")) -> Único | P25: B2 (código de sabor novo); B3 (embalagem C1 assumida – item cadastrado a granel) | Q25: Unidade cadastrada "Cx" diverge do padrão Kg dos demais gelatos.
A26: PF | B26: Produto Acabado | C26: PF-00031 | D26: Picolé Yeez s/ Lactose Limão | E26: Un | F26: 23 | G26: PC | H26: 207 | I26: XX | J26: TR | K26: =IF(OR(G26="",H26="",I26=""),"",G26&H26&I26&J26) -> PC207XXTR | L26: Picolé Limão - A definir - Tradicional | M26: PC = Picolé | 207 = Base Frutas – Limão | XX = gramatura/embalagem a definir | TR = Tradicional | N26: Pendente | O26: =IF(K26="","",IF(COUNTIF($K$5:$K$327,K26)>1,"DUPLICADO","Único")) -> Único | P26: B3 (gramatura/embalagem não identificável no cadastro); B2 (código de sabor novo) | Q26: Cadastro não informa gramatura; ver aba Matriz Picolé (55/60/70/90 ou C2). Marca (YEEZ) não faz parte do SKU: mesmo sabor Luna gera código idêntico.
A27: PF | B27: Produto Acabado | C27: PF-00032 | D27: Picolé Yeez s/ Lactose Uva | F27: 0 | G27: PC | H27: 203 | I27: XX | J27: TR | K27: =IF(OR(G27="",H27="",I27=""),"",G27&H27&I27&J27) -> PC203XXTR | L27: Picolé Uva - A definir - Tradicional | M27: PC = Picolé | 203 = Base Frutas – Uva | XX = gramatura/embalagem a definir | TR = Tradicional | N27: Pendente | O27: =IF(K27="","",IF(COUNTIF($K$5:$K$327,K27)>1,"DUPLICADO","Único")) -> Único | P27: B3 (gramatura/embalagem não identificável no cadastro) | Q27: Cadastro não informa gramatura; ver aba Matriz Picolé (55/60/70/90 ou C2). Marca (YEEZ) não faz parte do SKU: mesmo sabor Luna gera código idêntico.
A28: PF | B28: Produto Acabado | C28: PF-00033 | D28: Picolé Yeez s/ Lactose Abacaxi c/ Hortelã | E28: Un | F28: 31 | G28: PC | H28: 204 | I28: XX | J28: TR | K28: =IF(OR(G28="",H28="",I28=""),"",G28&H28&I28&J28) -> PC204XXTR | L28: Picolé Abacaxi c/ Hortelã - A definir - Tradicional | M28: PC = Picolé | 204 = Base Frutas – Abacaxi c/ Hortelã | XX = gramatura/embalagem a definir | TR = Tradicional | N28: Pendente | O28: =IF(K28="","",IF(COUNTIF($K$5:$K$327,K28)>1,"DUPLICADO","Único")) -> Único | P28: B3 (gramatura/embalagem não identificável no cadastro); B2 (código de sabor novo) | Q28: Cadastro não informa gramatura; ver aba Matriz Picolé (55/60/70/90 ou C2). Marca (YEEZ) não faz parte do SKU: mesmo sabor Luna gera código idêntico.
A29: PF | B29: Produto Acabado | C29: PF-00034 | D29: Picolé Yeez s/ Lactose Manga | E29: Un | F29: 0 | G29: PC | H29: 200 | I29: XX | J29: TR | K29: =IF(OR(G29="",H29="",I29=""),"",G29&H29&I29&J29) -> PC200XXTR | L29: Picolé Manga - A definir - Tradicional | M29: PC = Picolé | 200 = Base Frutas – Manga | XX = gramatura/embalagem a definir | TR = Tradicional | N29: Pendente | O29: =IF(K29="","",IF(COUNTIF($K$5:$K$327,K29)>1,"DUPLICADO","Único")) -> Único | P29: B3 (gramatura/embalagem não identificável no cadastro) | Q29: Cadastro não informa gramatura; ver aba Matriz Picolé (55/60/70/90 ou C2). Marca (YEEZ) não faz parte do SKU: mesmo sabor Luna gera código idêntico.
A30: PF | B30: Produto Acabado | C30: PF-00035 | D30: Picolé Yeez s/ Lactose Goiaba | E30: Un | F30: 12 | G30: PC | H30: 206 | I30: XX | J30: TR | K30: =IF(OR(G30="",H30="",I30=""),"",G30&H30&I30&J30) -> PC206XXTR | L30: Picolé Goiaba - A definir - Tradicional | M30: PC = Picolé | 206 = Base Frutas – Goiaba | XX = gramatura/embalagem a definir | TR = Tradicional | N30: Pendente | O30: =IF(K30="","",IF(COUNTIF($K$5:$K$327,K30)>1,"DUPLICADO","Único")) -> Único | P30: B3 (gramatura/embalagem não identificável no cadastro); B2 (código de sabor novo) | Q30: Cadastro não informa gramatura; ver aba Matriz Picolé (55/60/70/90 ou C2). Marca (YEEZ) não faz parte do SKU: mesmo sabor Luna gera código idêntico.
A31: PF | B31: Produto Acabado | C31: PF-00036 | D31: Picolé Yeez s/ Lactose Morango | E31: CX | F31: 0 | G31: PC | H31: 201 | I31: XX | J31: TR | K31: =IF(OR(G31="",H31="",I31=""),"",G31&H31&I31&J31) -> PC201XXTR | L31: Picolé Morango - A definir - Tradicional | M31: PC = Picolé | 201 = Base Frutas – Morango | XX = gramatura/embalagem a definir | TR = Tradicional | N31: Pendente | O31: =IF(K31="","",IF(COUNTIF($K$5:$K$327,K31)>1,"DUPLICADO","Único")) -> Único | P31: B3 (gramatura/embalagem não identificável no cadastro) | Q31: Cadastro não informa gramatura; ver aba Matriz Picolé (55/60/70/90 ou C2). Marca (YEEZ) não faz parte do SKU: mesmo sabor Luna gera código idêntico.
A32: PF | B32: Produto Acabado | C32: PF-00037 | D32: Picolé Yeez s/ Lactose Açaí | E32: Un | F32: 6 | G32: PC | H32: 205 | I32: XX | J32: TR | K32: =IF(OR(G32="",H32="",I32=""),"",G32&H32&I32&J32) -> PC205XXTR | L32: Picolé Açaí - A definir - Tradicional | M32: PC = Picolé | 205 = Base Frutas – Açaí | XX = gramatura/embalagem a definir | TR = Tradicional | N32: Pendente | O32: =IF(K32="","",IF(COUNTIF($K$5:$K$327,K32)>1,"DUPLICADO","Único")) -> Único | P32: B3 (gramatura/embalagem não identificável no cadastro); B2 (código de sabor novo) | Q32: Cadastro não informa gramatura; ver aba Matriz Picolé (55/60/70/90 ou C2). Marca (YEEZ) não faz parte do SKU: mesmo sabor Luna gera código idêntico.
A33: PF | B33: Produto Acabado | C33: PF-00038 | D33: Picolé Yeez s/ Lactose Melancia c/ Frutas | F33: 0 | G33: PC | H33: 301 | I33: XX | J33: TR | K33: =IF(OR(G33="",H33="",I33=""),"",G33&H33&I33&J33) -> PC301XXTR | L33: Picolé Melancia c/ Frutas - A definir - Tradicional | M33: PC = Picolé | 301 = Pedaços de Frutas – Melancia c/ Frutas | XX = gramatura/embalagem a definir | TR = Tradicional | N33: Pendente | O33: =IF(K33="","",IF(COUNTIF($K$5:$K$327,K33)>1,"DUPLICADO","Único")) -> Único | P33: B3 (gramatura/embalagem não identificável no cadastro); B2 (código de sabor novo); B2 (classe a validar) | Q33: Cadastro não informa gramatura; ver aba Matriz Picolé (55/60/70/90 ou C2). Marca (YEEZ) não faz parte do SKU: mesmo sabor Luna gera código idêntico.
A34: PF | B34: Produto Acabado | C34: PF-00039 | D34: Picolé Yeez Leite ChocoYeez | E34: Un | F34: 73 | G34: PC | H34: 105 | I34: XX | J34: TR | K34: =IF(OR(G34="",H34="",I34=""),"",G34&H34&I34&J34) -> PC105XXTR | L34: Picolé ChocoYeez - A definir - Tradicional | M34: PC = Picolé | 105 = Ao Leite – ChocoYeez | XX = gramatura/embalagem a definir | TR = Tradicional | N34: Pendente | O34: =IF(K34="","",IF(COUNTIF($K$5:$K$327,K34)>1,"DUPLICADO","Único")) -> Único | P34: B3 (gramatura/embalagem não identificável no cadastro); B2 (código de sabor novo) | Q34: Cadastro não informa gramatura; ver aba Matriz Picolé (55/60/70/90 ou C2). Marca (YEEZ) não faz parte do SKU: mesmo sabor Luna gera código idêntico.
A35: PF | B35: Produto Acabado | C35: PF-00040 | D35: Picolé Yeez Leite Coco Branco | E35: Un | F35: 13 | G35: PC | H35: 100 | I35: XX | J35: TR | K35: =IF(OR(G35="",H35="",I35=""),"",G35&H35&I35&J35) -> PC100XXTR | L35: Picolé Coco Branco - A definir - Tradicional | M35: PC = Picolé | 100 = Ao Leite – Coco Branco | XX = gramatura/embalagem a definir | TR = Tradicional | N35: Pendente | O35: =IF(K35="","",IF(COUNTIF($K$5:$K$327,K35)>1,"DUPLICADO","Único")) -> Único | P35: B3 (gramatura/embalagem não identificável no cadastro) | Q35: Cadastro não informa gramatura; ver aba Matriz Picolé (55/60/70/90 ou C2). Marca (YEEZ) não faz parte do SKU: mesmo sabor Luna gera código idêntico.
A36: PF | B36: Produto Acabado | C36: PF-00041 | D36: Picolé Yeez Leite Coco Queimado | E36: Un | F36: 19 | G36: PC | H36: 101 | I36: XX | J36: TR | K36: =IF(OR(G36="",H36="",I36=""),"",G36&H36&I36&J36) -> PC101XXTR | L36: Picolé Coco Queimado - A definir - Tradicional | M36: PC = Picolé | 101 = Ao Leite – Coco Queimado | XX = gramatura/embalagem a definir | TR = Tradicional | N36: Pendente | O36: =IF(K36="","",IF(COUNTIF($K$5:$K$327,K36)>1,"DUPLICADO","Único")) -> Único | P36: B3 (gramatura/embalagem não identificável no cadastro) | Q36: Cadastro não informa gramatura; ver aba Matriz Picolé (55/60/70/90 ou C2). Marca (YEEZ) não faz parte do SKU: mesmo sabor Luna gera código idêntico.
A37: PF | B37: Produto Acabado | C37: PF-00042 | D37: Picolé Yeez Leite Mousse de Maracujá | E37: Un | F37: 0 | G37: PC | H37: 404 | I37: XX | J37: TR | K37: =IF(OR(G37="",H37="",I37=""),"",G37&H37&I37&J37) -> PC404XXTR | L37: Picolé Mousse de Maracujá - A definir - Tradicional | M37: PC = Picolé | 404 = Recheados – Mousse de Maracujá | XX = gramatura/embalagem a definir | TR = Tradicional | N37: Pendente | O37: =IF(K37="","",IF(COUNTIF($K$5:$K$327,K37)>1,"DUPLICADO","Único")) -> Único | P37: B3 (gramatura/embalagem não identificável no cadastro) | Q37: Cadastro não informa gramatura; ver aba Matriz Picolé (55/60/70/90 ou C2). Marca (YEEZ) não faz parte do SKU: mesmo sabor Luna gera código idêntico. Sabor 404 do modelo (Recheados), embora o cadastro Yeez o classifique como "Leite".
A38: PF | B38: Produto Acabado | C38: PF-00043 | D38: Picolé Yeez Leite Romeu e Julieta | E38: Un | F38: 3 | G38: PC | H38: 407 | I38: XX | J38: TR | K38: =IF(OR(G38="",H38="",I38=""),"",G38&H38&I38&J38) -> PC407XXTR | L38: Picolé Romeu e Julieta - A definir - Tradicional | M38: PC = Picolé | 407 = Recheados – Romeu e Julieta | XX = gramatura/embalagem a definir | TR = Tradicional | N38: Pendente | O38: =IF(K38="","",IF(COUNTIF($K$5:$K$327,K38)>1,"DUPLICADO","Único")) -> Único | P38: B3 (gramatura/embalagem não identificável no cadastro); B2 (código de sabor novo); B2 (classe a validar) | Q38: Cadastro não informa gramatura; ver aba Matriz Picolé (55/60/70/90 ou C2). Marca (YEEZ) não faz parte do SKU: mesmo sabor Luna gera código idêntico.
A39: PF | B39: Produto Acabado | C39: PF-00044 | D39: Picolé Passione Yeez ChocoBrownie | E39: Un | F39: 22 | G39: PC | H39: 400 | I39: XX | J39: TR | K39: =IF(OR(G39="",H39="",I39=""),"",G39&H39&I39&J39) -> PC400XXTR | L39: Picolé ChocoBrownie - A definir - Tradicional | M39: PC = Picolé | 400 = Recheados – ChocoBrownie | XX = gramatura/embalagem a definir | TR = Tradicional | N39: Pendente | O39: =IF(K39="","",IF(COUNTIF($K$5:$K$327,K39)>1,"DUPLICADO","Único")) -> Único | P39: B3 (gramatura/embalagem não identificável no cadastro) | Q39: Cadastro não informa gramatura; ver aba Matriz Picolé (55/60/70/90 ou C2). Marca (YEEZ) não faz parte do SKU: mesmo sabor Luna gera código idêntico.
A40: PF | B40: Produto Acabado | C40: PF-00045 | D40: Picolé Passione Yeez Doce de Leite | E40: Un | F40: 48 | G40: PC | H40: 401 | I40: XX | J40: TR | K40: =IF(OR(G40="",H40="",I40=""),"",G40&H40&I40&J40) -> PC401XXTR | L40: Picolé Doce de Leite - A definir - Tradicional | M40: PC = Picolé | 401 = Recheados – Doce de Leite | XX = gramatura/embalagem a definir | TR = Tradicional | N40: Pendente | O40: =IF(K40="","",IF(COUNTIF($K$5:$K$327,K40)>1,"DUPLICADO","Único")) -> Único | P40: B3 (gramatura/embalagem não identificável no cadastro) | Q40: Cadastro não informa gramatura; ver aba Matriz Picolé (55/60/70/90 ou C2). Marca (YEEZ) não faz parte do SKU: mesmo sabor Luna gera código idêntico.
A41: PF | B41: Produto Acabado | C41: PF-00046 | D41: Picolé Passione Yeez Maracujá c/ Leite Condensado | E41: CX | F41: 0 | G41: PC | H41: 106 | I41: XX | J41: TR | K41: =IF(OR(G41="",H41="",I41=""),"",G41&H41&I41&J41) -> PC106XXTR | L41: Picolé Maracujá c/ Leite Condensado - A definir - Tradicional | M41: PC = Picolé | 106 = Ao Leite – Maracujá c/ Leite Condensado | XX = gramatura/embalagem a definir | TR = Tradicional | N41: Pendente | O41: =IF(K41="","",IF(COUNTIF($K$5:$K$327,K41)>1,"DUPLICADO","Único")) -> Único | P41: B3 (gramatura/embalagem não identificável no cadastro); B2 (código de sabor novo); B2 (classe a validar) | Q41: Cadastro não informa gramatura; ver aba Matriz Picolé (55/60/70/90 ou C2). Marca (YEEZ) não faz parte do SKU: mesmo sabor Luna gera código idêntico.
...

Sheet Matriz Picolé
A1: Matriz de SKUs de picolé: cada sabor × cada embalagem prevista no modelo
A2: O cadastro do sistema não informa a gramatura/embalagem do picolé. Esta matriz mostra todas as combinações do modelo para a Técnica indicar quais são vendidas. SKU = "PC" & sabor & tamanho & linha.
G3: Gramatura de 55 g | H3: Gramatura de 60 g | I3: Gramatura de 70 g | J3: Gramatura de 90 g | K3: Caixa c/ 20 un.
A4: Sabor (Bloco 2) | B4: Classe | C4: Sabor | D4: Origem do código | E4: No sistema? | F4: Linha (Bloco 4) | G4: 55 | H4: 60 | I4: 70 | J4: 90 | K4: C2
A5: 100 | B5: Ao Leite | C5: Coco Branco | D5: Modelo | E5: Sim | F5: TR | G5: ="PC"&$A5&G$4&$F5 -> PC10055TR | H5: ="PC"&$A5&H$4&$F5 -> PC10060TR | I5: ="PC"&$A5&I$4&$F5 -> PC10070TR | J5: ="PC"&$A5&J$4&$F5 -> PC10090TR | K5: ="PC"&$A5&K$4&$F5 -> PC100C2TR
A6: 101 | B6: Ao Leite | C6: Coco Queimado | D6: Modelo | E6: Sim | F6: TR | G6: ="PC"&$A6&G$4&$F6 -> PC10155TR | H6: ="PC"&$A6&H$4&$F6 -> PC10160TR | I6: ="PC"&$A6&I$4&$F6 -> PC10170TR | J6: ="PC"&$A6&J$4&$F6 -> PC10190TR | K6: ="PC"&$A6&K$4&$F6 -> PC101C2TR
A7: 102 | B7: Ao Leite | C7: Açaí c/ Leite Condensado | D7: Proposto | E7: Sim | F7: TR | G7: ="PC"&$A7&G$4&$F7 -> PC10255TR | H7: ="PC"&$A7&H$4&$F7 -> PC10260TR | I7: ="PC"&$A7&I$4&$F7 -> PC10270TR | J7: ="PC"&$A7&J$4&$F7 -> PC10290TR | K7: ="PC"&$A7&K$4&$F7 -> PC102C2TR
A8: 103 | B8: Ao Leite | C8: Algodão Doce | D8: Proposto | E8: Sim | F8: TR | G8: ="PC"&$A8&G$4&$F8 -> PC10355TR | H8: ="PC"&$A8&H$4&$F8 -> PC10360TR | I8: ="PC"&$A8&I$4&$F8 -> PC10370TR | J8: ="PC"&$A8&J$4&$F8 -> PC10390TR | K8: ="PC"&$A8&K$4&$F8 -> PC103C2TR
A9: 104 | B9: Ao Leite | C9: Chocolate Zero | D9: Proposto | E9: Sim | F9: ZR | G9: ="PC"&$A9&G$4&$F9 -> PC10455ZR | H9: ="PC"&$A9&H$4&$F9 -> PC10460ZR | I9: ="PC"&$A9&I$4&$F9 -> PC10470ZR | J9: ="PC"&$A9&J$4&$F9 -> PC10490ZR | K9: ="PC"&$A9&K$4&$F9 -> PC104C2ZR
A10: 105 | B10: Ao Leite | C10: ChocoYeez | D10: Proposto | E10: Sim | F10: TR | G10: ="PC"&$A10&G$4&$F10 -> PC10555TR | H10: ="PC"&$A10&H$4&$F10 -> PC10560TR | I10: ="PC"&$A10&I$4&$F10 -> PC10570TR | J10: ="PC"&$A10&J$4&$F10 -> PC10590TR | K10: ="PC"&$A10&K$4&$F10 -> PC105C2TR
A11: 106 | B11: Ao Leite | C11: Maracujá c/ Leite Condensado | D11: Proposto | E11: Sim | F11: TR | G11: ="PC"&$A11&G$4&$F11 -> PC10655TR | H11: ="PC"&$A11&H$4&$F11 -> PC10660TR | I11: ="PC"&$A11&I$4&$F11 -> PC10670TR | J11: ="PC"&$A11&J$4&$F11 -> PC10690TR | K11: ="PC"&$A11&K$4&$F11 -> PC106C2TR
A12: 107 | B12: Ao Leite | C12: Morango c/ Leite Condensado | D12: Proposto | E12: Sim | F12: TR | G12: ="PC"&$A12&G$4&$F12 -> PC10755TR | H12: ="PC"&$A12&H$4&$F12 -> PC10760TR | I12: ="PC"&$A12&I$4&$F12 -> PC10770TR | J12: ="PC"&$A12&J$4&$F12 -> PC10790TR | K12: ="PC"&$A12&K$4&$F12 -> PC107C2TR
A13: 200 | B13: Base Frutas | C13: Manga | D13: Modelo | E13: Sim | F13: TR | G13: ="PC"&$A13&G$4&$F13 -> PC20055TR | H13: ="PC"&$A13&H$4&$F13 -> PC20060TR | I13: ="PC"&$A13&I$4&$F13 -> PC20070TR | J13: ="PC"&$A13&J$4&$F13 -> PC20090TR | K13: ="PC"&$A13&K$4&$F13 -> PC200C2TR
A14: 201 | B14: Base Frutas | C14: Morango | D14: Modelo | E14: Sim | F14: TR | G14: ="PC"&$A14&G$4&$F14 -> PC20155TR | H14: ="PC"&$A14&H$4&$F14 -> PC20160TR | I14: ="PC"&$A14&I$4&$F14 -> PC20170TR | J14: ="PC"&$A14&J$4&$F14 -> PC20190TR | K14: ="PC"&$A14&K$4&$F14 -> PC201C2TR
A15: 203 | B15: Base Frutas | C15: Uva | D15: Modelo | E15: Sim | F15: TR | G15: ="PC"&$A15&G$4&$F15 -> PC20355TR | H15: ="PC"&$A15&H$4&$F15 -> PC20360TR | I15: ="PC"&$A15&I$4&$F15 -> PC20370TR | J15: ="PC"&$A15&J$4&$F15 -> PC20390TR | K15: ="PC"&$A15&K$4&$F15 -> PC203C2TR
A16: 204 | B16: Base Frutas | C16: Abacaxi c/ Hortelã | D16: Proposto | E16: Sim | F16: TR | G16: ="PC"&$A16&G$4&$F16 -> PC20455TR | H16: ="PC"&$A16&H$4&$F16 -> PC20460TR | I16: ="PC"&$A16&I$4&$F16 -> PC20470TR | J16: ="PC"&$A16&J$4&$F16 -> PC20490TR | K16: ="PC"&$A16&K$4&$F16 -> PC204C2TR
... A30: 408 | B30: Recheados | C30: Torta de Limão | D30: Proposto | E30: Sim | F30: TR | G30: ="PC"&$A30&G$4&$F30 -> PC40855TR | H30: ="PC"&$A30&H$4&$F30 -> PC40860TR | I30: ="PC"&$A30&I$4&$F30 -> PC40870TR | J30: ="PC"&$A30&J$4&$F30 -> PC40890TR | K30: ="PC"&$A30&K$4&$F30 -> PC408C2TR

Sheet Dicionário de códigos
A1: Dicionário de códigos usados neste relatório
A2: Origem: Modelo = tabelas dos arquivos de modelo · Lista de frutas = lista_de_frutas_A_Z.xlsx · Proposto = criado nesta análise, pendente de validação. A coluna "Nº de produtos" conta o uso na aba SKUs.
A4: Família | B4: Bloco | C4: Código | D4: Significado | E4: Origem | F4: Observação | G4: Nº de produtos
A5: PF | B5: Bloco 1 – Tipo | C5: GL | D5: Gelato | E5: Modelo | G5: =COUNTIFS(SKUs!$A$5:$A$327,A5,SKUs!$G$5:$G$327,C5) -> 48
A6: PF | B6: Bloco 1 – Tipo | C6: PC | D6: Picolé | E6: Modelo | G6: =COUNTIFS(SKUs!$A$5:$A$327,A6,SKUs!$G$5:$G$327,C6) -> 24
A7: PF | B7: Bloco 2 – Sabor (GL) | C7: 101 | D7: Ao Leite – Chocolate Belga | E7: Modelo | F7: Sabor de referência do modelo | G7: =COUNTIFS(SKUs!$A$5:$A$327,A7,SKUs!$H$5:$H$327,C7,SKUs!$G$5:$G$327,"GL") -> 2
A8: PF | B8: Bloco 2 – Sabor (GL) | C8: 102 | D8: Ao Leite – Banoffee | E8: Proposto | G8: =COUNTIFS(SKUs!$A$5:$A$327,A8,SKUs!$H$5:$H$327,C8,SKUs!$G$5:$G$327,"GL") -> 1
A9: PF | B9: Bloco 2 – Sabor (GL) | C9: 103 | D9: Ao Leite – Chocolate Branco | E9: Proposto | G9: =COUNTIFS(SKUs!$A$5:$A$327,A9,SKUs!$H$5:$H$327,C9,SKUs!$G$5:$G$327,"GL") -> 1
A10: PF | B10: Bloco 2 – Sabor (GL) | C10: 104 | D10: Ao Leite – Chocolate Crocante | E10: Proposto | G10: =COUNTIFS(SKUs!$A$5:$A$327,A10,SKUs!$H$5:$H$327,C10,SKUs!$G$5:$G$327,"GL") -> 1
A11: PF | B11: Bloco 2 – Sabor (GL) | C11: 105 | D11: Ao Leite – Chocolate Dubai | E11: Proposto | G11: =COUNTIFS(SKUs!$A$5:$A$327,A11,SKUs!$H$5:$H$327,C11,SKUs!$G$5:$G$327,"GL") -> 1
A12: PF | B12: Bloco 2 – Sabor (GL) | C12: 106 | D12: Ao Leite – Chocolate Intenso | E12: Proposto | G12: =COUNTIFS(SKUs!$A$5:$A$327,A12,SKUs!$H$5:$H$327,C12,SKUs!$G$5:$G$327,"GL") -> 1
A13: PF | B13: Bloco 2 – Sabor (GL) | C13: 107 | D13: Ao Leite – Coco Branco | E13: Proposto | G13: =COUNTIFS(SKUs!$A$5:$A$327,A13,SKUs!$H$5:$H$327,C13,SKUs!$G$5:$G$327,"GL") -> 3
A14: PF | B14: Bloco 2 – Sabor (GL) | C14: 108 | D14: Ao Leite – Coco Queimado | E14: Proposto | G14: =COUNTIFS(SKUs!$A$5:$A$327,A14,SKUs!$H$5:$H$327,C14,SKUs!$G$5:$G$327,"GL") -> 1
A15: PF | B15: Bloco 2 – Sabor (GL) | C15: 109 | D15: Ao Leite – Creme de Morango | E15: Proposto | G15: =COUNTIFS(SKUs!$A$5:$A$327,A15,SKUs!$H$5:$H$327,C15,SKUs!$G$5:$G$327,"GL") -> 3
A16: PF | B16: Bloco 2 – Sabor (GL) | C16: 110 | D16: Ao Leite – Doce de Leite | E16: Proposto | G16: =COUNTIFS(SKUs!$A$5:$A$327,A16,SKUs!$H$5:$H$327,C16,SKUs!$G$5:$G$327,"GL") -> 3
A17: PF | B17: Bloco 2 – Sabor (GL) | C17: 111 | D17: Ao Leite – Floresta Negra | E17: Proposto | G17: =COUNTIFS(SKUs!$A$5:$A$327,A17,SKUs!$H$5:$H$327,C17,SKUs!$G$5:$G$327,"GL") -> 1
A18: PF | B18: Bloco 2 – Sabor (GL) | C18: 112 | D18: Ao Leite – Gelato de Café | E18: Proposto | G18: =COUNTIFS(SKUs!$A$5:$A$327,A18,SKUs!$H$5:$H$327,C18,SKUs!$G$5:$G$327,"GL") -> 1
A19: PF | B19: Bloco 2 – Sabor (GL) | C19: 113 | D19: Ao Leite – Gianduia | E19: Proposto | G19: =COUNTIFS(SKUs!$A$5:$A$327,A19,SKUs!$H$5:$H$327,C19,SKUs!$G$5:$G$327,"GL") -> 1
... A35: PF | B35: Bloco 2 – Sabor (GL) | C35: 129 | D35: Ao Leite – Yogurt com Jabuticaba | E35: Proposto | G35: =COUNTIFS(SKUs!$A$5:$A$327,A35,SKUs!$H$5:$H$327,C35,SKUs!$G$5:$G$327,"GL") -> 1
A36: PF | B36: Bloco 2 – Sabor (GL) | C36: 200 | D36: Sorbet – Sorbet Manga | E36: Modelo | F36: Exemplo ilustrativo do modelo – sabor a confirmar | G36: =COUNTIFS(SKUs!$A$5:$A$327,A36,SKUs!$H$5:$H$327,C36,SKUs!$G$5:$G$327,"GL") -> 2
A37: PF | B37: Bloco 2 – Sabor (GL) | C37: 201 | D37: Sorbet – Sorbet Frutas Vermelhas | E37: Proposto | G37: =COUNTIFS(SKUs!$A$5:$A$327,A37,SKUs!$H$5:$H$327,C37,SKUs!$G$5:$G$327,"GL") -> 2
A38: PF | B38: Bloco 2 – Sabor (GL) | C38: 202 | D38: Sorbet – Sorbet Grape Fruit | E38: Proposto | G38: =COUNTIFS(SKUs!$A$5:$A$327,A38,SKUs!$H$5:$H$327,C38,SKUs!$G$5:$G$327,"GL") -> 1
A39: PF | B39: Bloco 2 – Sabor (GL) | C39: 203 | D39: Sorbet – Sorbet Limão | E39: Proposto | G39: =COUNTIFS(SKUs!$A$5:$A$327,A39,SKUs!$H$5:$H$327,C39,SKUs!$G$5:$G$327,"GL") -> 1
A40: PF | B40: Bloco 2 – Sabor (GL) | C40: 204 | D40: Sorbet – Sorbet Manga com Maracujá Zero | E40: Proposto | G40: =COUNTIFS(SKUs!$A$5:$A$327,A40,SKUs!$H$5:$H$327,C40,SKUs!$G$5:$G$327,"GL") -> 1
A41: PF | B41: Bloco 2 – Sabor (GL) | C41: 205 | D41: Sorbet – Sorbet Maracujá | E41: Proposto | G41: =COUNTIFS(SKUs!$A$5:$A$327,A41,SKUs!$H$5:$H$327,C41,SKUs!$G$5:$G$327,"GL") -> 1
A42: PF | B42: Bloco 2 – Sabor (GL) | C42: 206 | D42: Sorbet – Sorbet Morango | E42: Proposto | G42: =COUNTIFS(SKUs!$A$5:$A$327,A42,SKUs!$H$5:$H$327,C42,SKUs!$G$5:$G$327,"GL") -> 1
A43: PF | B43: Bloco 2 – Sabor (GL) | C43: 207 | D43: Sorbet – Sorbet Zeríssimo | E43: Proposto | G43: =COUNTIFS(SKUs!$A$5:$A$327,A43,SKUs!$H$5:$H$327,C43,SKUs!$G$5:$G$327,"GL") -> 1
A44: PF | B44: Bloco 2 – Sabor (PC) | C44: 100 | D44: Ao Leite – Coco Branco | E44: Modelo | G44: =COUNTIFS(SKUs!$A$5:$A$327,A44,SKUs!$H$5:$H$327,C44,SKUs!$G$5:$G$327,"PC") -> 1
A45: PF | B45: Bloco 2 – Sabor (PC) | C45: 101 | D45: Ao Leite – Coco Queimado | E45: Modelo | G45: =COUNTIFS(SKUs!$A$5:$A$327,A45,SKUs!$H$5:$H$327,C45,SKUs!$G$5:$G$327,"PC") -> 1
A46: PF | B46: Bloco 2 – Sabor (PC) | C46: 102 | D46: Ao Leite – Açaí c/ Leite Condensado | E46: Proposto | F46: Classe a validar | G46: =COUNTIFS(SKUs!$A$5:$A$327,A46,SKUs!$H$5:$H$327,C46,SKUs!$G$5:$G$327,"PC") -> 1
A47: PF | B47: Bloco 2 – Sabor (PC) | C47: 103 | D47: Ao Leite – Algodão Doce | E47: Proposto | F47: Classe a validar | G47: =COUNTIFS(SKUs!$A$5:$A$327,A47,SKUs!$H$5:$H$327,C47,SKUs!$G$5:$G$327,"PC") -> 1
A48: PF | B48: Bloco 2 – Sabor (PC) | C48: 104 | D48: Ao Leite – Chocolate Zero | E48: Proposto | F48: Classe a validar | G48: =COUNTIFS(SKUs!$A$5:$A$327,A48,SKUs!$H$5:$H$327,C48,SKUs!$G$5:$G$327,"PC") -> 1
A49: PF | B49: Bloco 2 – Sabor (PC) | C49: 105 | D49: Ao Leite – ChocoYeez | E49: Proposto | F49: Código novo na sequência da classe | G49: =COUNTIFS(SKUs!$A$5:$A$327,A49,SKUs!$H$5:$H$327,C49,SKUs!$G$5:$G$327,"PC") -> 1
A50: PF | B50: Bloco 2 – Sabor (PC) | C50: 106 | D50: Ao Leite – Maracujá c/ Leite Condensado | E50: Proposto | F50: Classe a validar | G50: =COUNTIFS(SKUs!$A$5:$A$327,A50,SKUs!$H$5:$H$327,C50,SKUs!$G$5:$G$327,"PC") -> 1
A51: PF | B51: Bloco 2 – Sabor (PC) | C51: 107 | D51: Ao Leite – Morango c/ Leite Condensado | E51: Proposto | F51: Classe a validar | G51: =COUNTIFS(SKUs!$A$5:$A$327,A51,SKUs!$H$5:$H$327,C51,SKUs!$G$5:$G$327,"PC") -> 1
A52: PF | B52: Bloco 2 – Sabor (PC) | C52: 200 | D52: Base Frutas – Manga | E52: Modelo | G52: =COUNTIFS(SKUs!$A$5:$A$327,A52,SKUs!$H$5:$H$327,C52,SKUs!$G$5:$G$327,"PC") -> 1
A53: PF | B53: Bloco 2 – Sabor (PC) | C53: 201 | D53: Base Frutas – Morango | E53: Modelo | G53: =COUNTIFS(SKUs!$A$5:$A$327,A53,SKUs!$H$5:$H$327,C53,SKUs!$G$5:$G$327,"PC") -> 1
A54: PF | B54: Bloco 2 – Sabor (PC) | C54: 203 | D54: Base Frutas – Uva | E54: Modelo | G54: =COUNTIFS(SKUs!$A$5:$A$327,A54,SKUs!$H$5:$H$327,C54,SKUs!$G$5:$G$327,"PC") -> 1
A55: PF | B55: Bloco 2 – Sabor (PC) | C55: 204 | D55: Base Frutas – Abacaxi c/ Hortelã | E55: Proposto | F55: Código novo na sequência da classe | G55: =COUNTIFS(SKUs!$A$5:$A$327,A55,SKUs!$H$5:$H$327,C55,SKUs!$G$5:$G$327,"PC") -> 1
A56: PF | B56: Bloco 2 – Sabor (PC) | C56: 205 | D56: Base Frutas – Açaí | E56: Proposto | F56: Código novo na sequência da classe | G56: =COUNTIFS(SKUs!$A$5:$A$327,A56,SKUs!$H$5:$H$327,C56,SKUs!$G$5:$G$327,"PC") -> 1
...

Sheet Pendências para a Técnica
A1: Pontos para decisão da área técnica
A2: Inconsistências encontradas nos modelos e decisões adotadas provisoriamente neste relatório. Preencher a última coluna para consolidar a validação.
A4: # | B4: Família | C4: Assunto | D4: O que foi encontrado | E4: Tratamento adotado neste relatório | F4: Decisão da área técnica
A5: 1 | B5: PF | C5: Código do balde | D5: Estrutura Base usa "BL"; aba Tipos e Simulador usam "B4" (Balde 4 L). | E5: Usado B4. Nenhum produto do sistema usa balde.
A6: 2 | B6: PF | C6: Caixa de gelato (C1) | D6: "Caixa 06" (Estrutura Base) vs "Caixa de 6200 L" (Tipos; o comentário do arquivo fala em 6,2 L). O sistema (embalagem padrão) e as OPs usam caixa de 6 kg. | E6: Assumido C1 = caixa de 6 kg para todos os gelatos cadastrados a granel. Confirmar unidade (kg ou L).
A7: 3 | B7: PF | C7: Códigos CP, CM, CG | D7: Aparecem no simulador de gelato com descrição "?" (indefinidos). | E7: Não utilizados. Definir significado (cuba pequena/média/grande?).
A8: 4 | B8: PF | C8: Potes de gelato | D8: Modelo: 12 = 120 g e 36 = 360 g. OPs: potes de 150 g e 360 g. Sistema: potes de 240 g e 360 g, e 1 produto "150ml" (proteico). | E8: Mantido 36. Criados 24 (240 g) e 15 (150) como PROPOSTA. Confirmar também se 12 = 120 g ou 150 g.
A9: 5 | B9: PF | C9: Gramatura/embalagem do picolé | D9: Modelo: 55/60/70/90 (Tipos) e 50/60/70/80/90 (Estrutura Base). OPs: palitos de 60 mL e 80 mL. O cadastro do sistema não informa a gramatura de nenhum picolé. | E9: SKU provisório com "XX" no Bloco 3 (status Pendente). Aba Matriz Picolé lista todas as combinações para a Técnica escolher.
A10: 6 | B10: PF | C10: Caixa de picolé (C2) | D10: Modelo: caixa com 20 un. (código C2; um comentário cita "CX20"). OPs: "Caixas de 12 unid.". | E10: Mantido C2 do modelo. Confirmar 12 ou 20 unidades. Itens do sistema com unidade "CX"/"Cx" (ex.: PF-00036, PF-00046) não têm regra para distinguir unidade de caixa.
A11: 7 | B11: PF | C11: Marca (Luna × Yeez) | D11: O modelo de picolé nomeia os sabores como "PICOLÉ LUNA …" e não há bloco de marca. O sistema só tem picolés Yeez; as OPs têm os mesmos sabores nas duas marcas. | E11: Códigos de sabor do modelo reaproveitados para os picolés Yeez. Hoje não há colisão no cadastro, mas Luna e Yeez do mesmo sabor teriam o mesmo SKU. Definir como diferenciar.
A12: 8 | B12: PF | C12: Linhas (Bloco 4) | D12: Tabela tem TR, ZR, VG, PT. Simulador cita também CB ("Venda Premium") e RC, sem definição. Produtos "Passione Plus" e "Passione" não têm linha equivalente. | E12: Todos TR, exceto ZR (Manga com Maracujá Zero, Sorbet Zeríssimo, Picolé Chocolate Zero) e PT (Chocolate Crocante Proteico), inferidos pelo nome.
A13: 9 | B13: PF | C13: Classes do picolé | D13: Estrutura Base: "Base Água"; aba Classes: "Base Frutas". Sabor 202 não existe (lacuna entre 201 e 203). | E13: Usado "Base Frutas"; código 202 não reutilizado (novos começam em 204).
A14: 10 | B14: PF | C14: Sabores novos | D14: O modelo define 12 sabores de picolé e 2 de gelato (referência). O sistema tem 24 sabores de picolé e cerca de 36 de gelato. | E14: Códigos novos atribuídos em sequência dentro da classe, em ordem alfabética (aba Dicionário). Classes marcadas "a validar": Algodão Doce, Chocolate Zero, Romeu e Julieta, Brigadeiro, Torta de Limão, Melancia c/ Frutas e os picolés "c/ Leite Condensado".
A15: 11 | B15: PF | C15: Chocolate Belga × Chocolate Intenso | D15: O modelo usa "Chocolate Belga Ao Leite" (101) como referência; o sistema não tem esse nome. Potes "Chocolate 240/360g" combinam com as embalagens "belga". | E15: Potes "Chocolate" → 101. "Chocolate Intenso" (granel) recebeu código próprio (106). Confirmar se são o mesmo produto. Mesma dúvida para pote "Morango" (assumido Creme de Morango) e pote "Coco" (assumido Coco Branco).
A16: 12 | B16: PF | C16: Sorbet 200 | D16: O modelo traz "Sorbet de Manga (sabor a confirmar)" como exemplo ilustrativo (comentário do arquivo). | E16: Usado 200 para Sorbet Manga e demais sorbets de 201 em diante. Confirmar.
... A36: 32 | B36: Geral | C36: Protheus | D36: O arquivo CARGA_SB1_PRODUTOS.csv traz 3 exemplos no padrão antigo (MP000001, PA000001). | E36: Os SKUs novos têm até 9 caracteres. Confirmar o tamanho do campo B1_COD no ambiente e o mapeamento de B1_TIPO na etapa de adequação.

Sheet Alertas de cadastro
A1: Alertas de qualidade do cadastro atual
A2: Observados durante a extração. Não afetam a regra do SKU, mas convém tratar na etapa de adequação.
A4: Tipo | B4: Códigos | C4: Descrição
A5: Registro vazio | B5: MP-00097 | C5: Sem nome, unidade e estoque.
A6: Provável duplicidade | B6: MP-00080 · MP-00123 | C6: "Sal refinado" e "Sal".
A7: Provável duplicidade | B7: MP-00085 · MP-00178 | C7: "Ácido cítrico" e "Acido citrico Anidro".
A8: Provável duplicidade | B8: MP-00093 · MP-00109 · MP-00110 | C8: "Cacao Miscela", "Cacau Micela" e "Cacau Micela - MEC" (grafias diferentes).
A9: Provável duplicidade | B9: MP-00098 · MP-00122 | C9: "Variegato Quello - MEC3" e "Variegato Quello".
A10: Provável duplicidade | B10: MP-00127 · MP-00128 · MP-00121 | C10: "Chocolate (Mocca)", "Crockolosi Meringa" e "Mescla Crockolosi Merengue c/ cho Branco" (pré-cadastros da planilha de gelato).
A11: Provável duplicidade | B11: MP-00115 · MP-00129 | C11: "Mescla de Morango com Pedaços (Variegato Fragola)" e "Mescla Morango".
A12: Provável duplicidade | B12: MP-00073 · MP-00142 | C12: "Ovo pasteurizado" e "Ovo".
A13: Provável duplicidade | B13: MP-00026 · MP-00161 · MP-00172 | C13: Três cadastros de coco seco: "ralado", "Coco Seco Freco" e "em escama".
A14: Provável duplicidade | B14: MP-00060 · MP-00061 · MP-00112 · MP-00125 | C14: Quatro cadastros de maracujá (com sementes, sem sementes, genérico e azedo).
A15: Provável duplicidade | B15: MP-00051 · MP-00052 | C15: "Leite em pó integral" e "Leite em pó Integral - Ninho" (marca).
... A22: Unidade inconsistente | B22: Vários | C22: Mesma unidade escrita de formas diferentes (Kg/kg, Un/unid/Pc, Cx/CX); gelatos em Kg, Cx ou Un.
